<robot
  name="RX60B-HB_5">
  <link
    name="base_link">
    <visual>
      <origin
        xyz="0 0 0"
        rpy="0 0 0" />
      <geometry>
        <mesh
          filename="package://rx60b_description/meshes/base_link.stl" />
      </geometry>
      <material
        name="">
        <color
          rgba="0.867 0.45 0.098 1" />
      </material>
    </visual>
    <collision>
      <origin
        xyz="0 0 0"
        rpy="0 0 0" />
      <geometry>
        <mesh
          filename="package://rx60b_description/meshes/base_link.stl" />
      </geometry>
    </collision>
  </link>
  <link
    name="powerconnector">
    <collision>
      <origin
        xyz="0 0 0"
        rpy="0 0 0" />
      <geometry>
        <mesh
          filename="package://rx60b_description/meshes/powerconnector.stl" />
      </geometry>
    </collision>
  </link>
  <joint name="powerconnector_joint" type="fixed">
    <origin
      xyz="-0.15 0 0.09"
      rpy="1.57079632679 1.57079632679 0" />
    <parent link="base_link" />
    <child link="powerconnector" />
    <axis xyz="1 0 0" />
  </joint>
  <link
    name="shoulder">
    <visual>
      <origin
        xyz="0 0 0"
        rpy="0 0 0" />
      <geometry>
        <mesh
          filename="package://rx60b_description/meshes/shoulder.stl" />
      </geometry>
      <material
        name="">
        <color
          rgba="0.867 0.45 0.098 1" />
      </material>
    </visual>
    <collision>
      <origin
        xyz="0 0 0"
        rpy="0 0 0" />
      <geometry>
        <mesh
          filename="package://rx60b_description/meshes/shoulder.stl" />
      </geometry>
    </collision>
  </link>
  <joint
    name="a1"
    type="revolute">
    <origin
      xyz="0 0 0.341"
      rpy="0 0 0" />
    <parent
      link="base_link" />
    <child
      link="shoulder" />
    <axis
      xyz="0 0 -1" />
    <limit
      lower="-3.14159265359"
      upper="3.14159265359"
      effort="0"
      velocity="0.2" />
  </joint>
  <link
    name="arm">
    <visual>
      <origin
        xyz="0 0 0"
        rpy="0 0 0" />
      <geometry>
        <mesh
          filename="package://rx60b_description/meshes/arm.stl" />
      </geometry>
      <material
        name="">
        <color
          rgba="0.867 0.45 0.098 1" />
      </material>
    </visual>
    <collision>
      <origin
        xyz="0 0 0"
        rpy="0 0 0" />
      <geometry>
        <mesh
          filename="package://rx60b_description/meshes/arm.stl" />
      </geometry>
    </collision>
  </link>
  <joint
    name="a2"
    type="revolute">
    <origin
      xyz="0 0.049 0"
      rpy="-1.57079632679 -1.57079632679 0" />
    <parent
      link="shoulder" />
    <child
      link="arm" />
    <axis
      xyz="0 0 -1" />
    <limit
      lower="-2.0943951"
      upper="2.0943951"
      effort="0"
      velocity="0.2" />
  </joint>
  <link
    name="elbow">
    <visual>
      <origin
        xyz="0 0 0"
        rpy="0 0 0" />
      <geometry>
        <mesh
          filename="package://rx60b_description/meshes/elbow.stl" />
      </geometry>
      <material
        name="">
        <color
          rgba="0.867 0.45 0.098 1" />
      </material>
    </visual>
    <collision>
      <origin
        xyz="0 0 0"
        rpy="0 0 0" />
      <geometry>
        <mesh
          filename="package://rx60b_description/meshes/elbow.stl" />
      </geometry>
    </collision>
  </link>
  <joint
    name="a3"
    type="revolute">
    <origin
      xyz="0.29 0 0"
      rpy="0 0 0" />
    <parent
      link="arm" />
    <child
      link="elbow" />
    <axis
      xyz="0 0 -1" />
    <limit
      lower="-2.2"
      upper="2.2"
      effort="0"
      velocity="0.2" />
  </joint>
  <link
    name="forearm">
    <visual>
      <origin
        xyz="0 0 0"
        rpy="0 0 1.57079632679" />
      <geometry>
        <mesh
          filename="package://rx60b_description/meshes/forearm.stl" />
      </geometry>
      <material
        name="">
        <color
          rgba="0.867 0.45 0.098 1" />
      </material>
    </visual>
    <collision>
      <origin
        xyz="0 0 0"
        rpy="0 0 1.57079632679" />
      <geometry>
        <mesh
          filename="package://rx60b_description/meshes/forearm.stl" />
      </geometry>
    </collision>
  </link>
  <joint
    name="a4"
    type="revolute">
    <origin
      xyz="0.11 0 0"
      rpy="0 1.57079632679 0" />
    <parent
      link="elbow" />
    <child
      link="forearm" />
    <axis
      xyz="0 0 -1" />
    <limit
      lower="-2.3387412"
      upper="2.3387412"
      effort="0"
      velocity="0.2" />
  </joint>
  <link
    name="wrist">
    <visual>
      <origin
        xyz="0 0 0"
        rpy="0 0 1.57079632679" />
      <geometry>
        <mesh
          filename="package://rx60b_description/meshes/wrist.stl" />
      </geometry>
      <material
        name="">
        <color
          rgba="0.792156862745098 0.819607843137255 0.933333333333333 1" />
      </material>
    </visual>
    <collision>
      <origin
        xyz="0 0 0"
        rpy="0 0 1.57079632679" />
      <geometry>
        <mesh
          filename="package://rx60b_description/meshes/wrist.stl" />
      </geometry>
    </collision>
  </link>
  <joint
    name="a5"
    type="revolute">
    <origin
      xyz="0 0 0.2"
      rpy="3.14159265359 1.57079632679 0" />
    <parent
      link="forearm" />
    <child
      link="wrist" />
    <axis
      xyz="0 0 -1" />
    <limit
      lower="-2"
      upper="2"
      effort="0"
      velocity="0.2" />
  </joint>
  <link
    name="tool_flange">
    <visual>
      <origin
        xyz="0 0 0"
        rpy="0 0 0" />
      <geometry>
        <mesh
          filename="package://rx60b_description/meshes/tool_flange.stl" />
      </geometry>
      <material
        name="">
        <color
          rgba="0.792156862745098 0.819607843137255 0.933333333333333 1" />
      </material>
    </visual>
    <collision>
      <origin
        xyz="0 0 0"
        rpy="0 0 0" />
      <geometry>
        <mesh
          filename="package://rx60b_description/meshes/tool_flange.stl" />
      </geometry>
    </collision>
  </link>
  <joint
    name="a6"
    type="revolute">
    <origin
      xyz="-0.07 0 0"
      rpy="0 1.57079632679 3.14159265359" />
    <parent
      link="wrist" />
    <child
      link="tool_flange" />
    <axis
      xyz="0 0 -1" />
    <limit
      lower="-2.0943951"
      upper="2.0943951"
      effort="0"
      velocity="0.2" />
  </joint>
  
  
  <link
    name="cameratool">
    <visual>
      <origin
        xyz="0 0 0"
        rpy="0 0 0" />
      <geometry>
        <mesh
          filename="package://rx60b_description/meshes/tool_visual.stl" />
      </geometry>
      <material
        name="">
        <color
          rgba="0.3 0.6 0.6 1" />
      </material>
    </visual>
    <collision>
      <origin
        xyz="0 0 0"
        rpy="0 0 0" />
      <geometry>
        <mesh
          filename="package://rx60b_description/meshes/tool_boundingbox.stl" />
      </geometry>
    </collision>
  </link>
  
  <joint
    name="toolmount"
    type="fixed">
    <origin
      xyz="0 0 0.0095"
      rpy="0 0 -0.785398163" />
    <parent
      link="tool_flange" />
    <child
      link="cameratool" />
    <axis
      xyz="1 0 0" />
  </joint>
  
  
  <link name="bumblebee_cam1"></link>
  <link name="bumblebee_cam2"></link>
  <joint
    name="bumblebee_cam1_joint"
    type="fixed">
    <origin
      xyz="-0.06 0.0 0.106114"
      rpy="-1.57079632679 0 0" />
    <parent link="cameratool" />
    <child link="bumblebee_cam1" />
    <axis xyz="1 0 0" />
  </joint>
  
  <joint
    name="bumblebee_cam2_joint"
    type="fixed">
    <origin
      xyz="0.06 0.0 0.106114"
      rpy="-1.57079632679 0 0" />
    <parent link="cameratool" />
    <child link="bumblebee_cam2" />
    <axis xyz="1 0 0" />
  </joint>
  
  
  <link name="asus_depthcam"></link>
  <link name="asus_rgbcam"></link>
  <link name="asus_projector"></link>
  <link name="camera_link"></link>
  
  <joint
    name="asus_depthcam_joint"
    type="fixed">
    <origin
      xyz="-0.046 0.052 0.056"
      rpy="1.57079632679 0 3.14159265359" />
    <parent link="cameratool" />
    <child link="asus_depthcam" />
    <axis xyz="1 0 0" />
  </joint>
  <joint
    name="asus_rgbcam_joint"
    type="fixed">
    <origin
      xyz="-0.0196 0.052 0.056"
      rpy="1.57079632679 0 3.14159265359" />
    <parent link="cameratool" />
    <child link="asus_rgbcam" />
    <axis xyz="1 0 0" />
  </joint>
  <joint
    name="asus_projector_joint"
    type="fixed">
    <origin
      xyz="0.0274 0.052 0.056"
      rpy="1.57079632679 0 3.14159265359" />
    <parent link="cameratool" />
    <child link="asus_projector" />
    <axis xyz="1 0 0" />
  </joint>
  <joint
    name="camera_link_joint"
    type="fixed">
    <origin
      xyz="0.0 0.052 0.056"
      rpy="0 0 1.57079632679" />
    <parent link="cameratool" />
    <child link="camera_link" />
    <axis xyz="1 0 0" />
  </joint>
  
<!--  
  <link name="collision_object">
    <collision>
      <geometry>
        <cylinder length="0.15" radius="0.08"/>
      </geometry>
    </collision>
  </link>
  <joint
    name="collision_object_joint"
    type="fixed">
    <origin
      xyz="0.0 0.0 0.75"
      rpy="0 0 0" />
    <parent link="base_link" />
    <child link="collision_object" />
    <axis xyz="1 0 0" />
  </joint>
-->
  
  <link name="collision_radiator">
    <collision>
      <geometry>
        <box size="0.3 2 0.52" />
      </geometry>
    </collision>
  </link>
  <joint
    name="collision_radiator_joint"
    type="fixed">
    <origin
      xyz="-0.65 0.0 0.0"
      rpy="0 0 0" />
    <parent link="base_link" />
    <child link="collision_radiator" />
    <axis xyz="1 0 0" />
  </joint>
  
  <link name="collision_table">
    <collision>
      <geometry>
        <box size="1.5 1.5 0.1" />
      </geometry>
    </collision>
  </link>
  <joint
    name="collision_table_joint"
    type="fixed">
    <origin
      xyz="0.0 0.0 -0.025"
      rpy="0 0 0" />
    <parent link="base_link" />
    <child link="collision_table" />
    <axis xyz="1 0 0" />
  </joint>

    
  <link name="collision_fence">
    <collision>
      <geometry>
        <box size="2 0.1 2" />
      </geometry>
    </collision>
  </link>
  <joint
    name="collision_fence_joint"
    type="fixed">
    <origin
      xyz="0.0 -0.79 0"
      rpy="0 0 0" />
    <parent link="base_link" />
    <child link="collision_fence" />
    <axis xyz="1 0 0" />
  </joint>
  
  <link name="collision_pole">
    <collision>
      <geometry>
        <box size="0.3 0.3 2" />
      </geometry>
    </collision>
  </link>
  <joint
    name="collision_pole_joint"
    type="fixed">
    <origin
      xyz="-0.65 -0.7 0"
      rpy="0 0 0" />
    <parent link="base_link" />
    <child link="collision_pole" />
    <axis xyz="1 0 0" />
  </joint>
  
  <link name="collision_wall">
    <collision>
      <geometry>
        <box size="0.01 2 2" />
      </geometry>
    </collision>
  </link>
  <joint
    name="collision_wall_joint"
    type="fixed">
    <origin
      xyz="-0.65 0 0"
      rpy="0 0 0" />
    <parent link="base_link" />
    <child link="collision_wall" />
    <axis xyz="1 0 0" />
  </joint>
  
</robot>
